<?xml version="1.0"?>

<robot name="inmoov" xmlns:xacro="http://ros.org/wiki/xacro">

<xacro:include filename="$(find inmoov_description)/urdf/materials.urdf.xacro" />

<xacro:macro name="arm" params="side flip covers">

  <link name="${side}_shoulder_base_link">
    <visual>
      <geometry>
        <mesh filename="package://inmoov_meshes/meshes/${side}_shoulder_base.stl" scale="0.001 0.001 0.001"/>
      </geometry>
      <origin rpy="0 0 0" xyz="0 0 0"/>
      <xacro:frame_color/>
    </visual>
  </link>

  <link name="${side}_shoulder_link">
    <visual>
      <geometry>
        <mesh filename="package://inmoov_meshes/meshes/${side}_shoulder.stl" scale="0.001 0.001 0.001"/>
      </geometry>
      <origin rpy="0 0 0" xyz="0 0 0"/>
      <xacro:frame_color/>
    </visual>
  </link>

  <link name="${side}_bicep_link">
    <visual>
      <geometry>
        <mesh filename="package://inmoov_meshes/meshes/bicep.stl" scale="0.001 0.001 0.001"/>
      </geometry>
      <origin rpy="0 0 0" xyz="0 0 0"/>
      <xacro:frame_color/>
    </visual>
  </link>

  <link name="${side}_bicepcover_link">
    <visual>
      <geometry>
        <mesh filename="package://inmoov_meshes/meshes/bicepcover.stl" scale="0.001 0.001 0.001"/>
      </geometry>
      <origin rpy="0 0 0" xyz="0 0 0"/>
      <xacro:cover_color/>
    </visual>
  </link>

  <link name="${side}_forearm_link">
    <visual>
      <geometry>
        <mesh filename="package://inmoov_meshes/meshes/${side}_forearm.stl" scale="0.001 0.001 0.001"/>
      </geometry>
      <origin rpy="0 0 0" xyz="${flip * 0.001} 0 0"/>
      <xacro:cover_color/>
    </visual>
  </link>

  <joint name="${side}_shoulder_lift_joint" type="revolute">
    <axis xyz="0 1 0"/>
    <limit effort="1000.0" lower="0.7" upper="-2.5" velocity="0.5"/>
    <origin rpy="0 0 0" xyz="0 ${flip * -0.012} -0.04"/>
    <parent link="${side}_shoulder_base_link"/>
    <child link="${side}_shoulder_link"/>
  </joint>

  <joint name="${side}_upper_arm_roll_joint" type="revolute">
    <axis xyz="0 0 1"/>
    <limit effort="1000.0" lower="-1.57" upper="1.57" velocity="0.5"/>
    <origin rpy="0 0 0" xyz="0 ${flip * -0.066} -0.060"/>
    <parent link="${side}_shoulder_link"/>
    <child link="${side}_bicep_link"/>
  </joint>

  <joint name="${side}_elbow_flex_joint" type="revolute">
    <axis xyz="0 1 0"/>
    <limit effort="1000.0" lower="-0.4" upper="-1.57" velocity="0.5"/>
    <origin rpy="0 0 0" xyz="-0.0278 0 -0.2235"/>
    <parent link="${side}_bicep_link"/>
    <child link="${side}_forearm_link"/>
  </joint>

  <joint name="${side}_bicepcover_joint" type="fixed">
    <origin rpy="0 0 0" xyz="0 0 0"/>
    <parent link="${side}_bicep_link"/>
    <child link="${side}_bicepcover_link"/>
  </joint>





</xacro:macro>



</robot>
