<?xml version="1.0" ?>
<!-- =================================================================================== -->
<!-- |    This document was autogenerated by xacro from inmoov_right_hand.urdf.xacro   | -->
<!-- |    EDITING THIS FILE BY HAND IS NOT RECOMMENDED                                 | -->
<!-- =================================================================================== -->
<robot name="inmoov_hand" xmlns:xacro="http://ros.org/wiki/xacro">
  <link name="base_link">
    <visual>
      <geometry>
        <cylinder length="0.0001" radius="0.26"/>
      </geometry>
      <origin rpy="0 0 0" xyz="0 0 0.055"/>
      <material name="invisible">
        <color rgba="0.3 0.3 0.3 0"/>
      </material>
    </visual>
  </link>
  <link name="r_hand_link">
    <visual>
      <geometry>
        <mesh filename="package://inmoov_meshes/meshes/r_hand.stl" scale="0.001 0.001 0.001"/>
      </geometry>
      <origin rpy="0 0 0" xyz="0 0 0"/>
      <material name="cframe">
        <color rgba="0.25 0.25 0.25 1"/>
      </material>
    </visual>
  </link>
  <link name="r_thumb1_link">
    <visual>
      <geometry>
        <mesh filename="package://inmoov_meshes/meshes/r_thumb5_1.stl" scale="0.001 0.001 0.001"/>
      </geometry>
      <origin rpy="3.1415 0 0" xyz="0 0 0"/>
      <material name="cframe">
        <color rgba="0.25 0.25 0.25 1"/>
      </material>
    </visual>
  </link>
  <link name="r_thumb2_link">
    <visual>
      <geometry>
        <mesh filename="package://inmoov_meshes/meshes/thumb5_2.stl" scale="0.001 0.001 0.001"/>
      </geometry>
      <origin rpy="0 0 3.1415" xyz="0 0 0"/>
      <material name="cframe">
        <color rgba="0.25 0.25 0.25 1"/>
      </material>
    </visual>
  </link>
  <link name="r_thumb3_link">
    <visual>
      <geometry>
        <mesh filename="package://inmoov_meshes/meshes/thumb5_3.stl" scale="0.001 0.001 0.001"/>
      </geometry>
      <origin rpy="0 0 3.1415" xyz="0 0 0"/>
      <material name="cframe">
        <color rgba="0.25 0.25 0.25 1"/>
      </material>
    </visual>
  </link>
  <link name="r_index1_link">
    <visual>
      <geometry>
        <mesh filename="package://inmoov_meshes/meshes/index3_1.stl" scale="0.001 0.001 0.001"/>
      </geometry>
      <origin rpy="0 0 3.1415" xyz="0 0 0"/>
      <material name="cframe">
        <color rgba="0.25 0.25 0.25 1"/>
      </material>
    </visual>
  </link>
  <link name="r_index2_link">
    <visual>
      <geometry>
        <mesh filename="package://inmoov_meshes/meshes/index3_2.stl" scale="0.001 0.001 0.001"/>
      </geometry>
      <origin rpy="0 0 3.1415" xyz="0 0 0"/>
      <material name="cframe">
        <color rgba="0.25 0.25 0.25 1"/>
      </material>
    </visual>
  </link>
  <link name="r_index3_link">
    <visual>
      <geometry>
        <mesh filename="package://inmoov_meshes/meshes/index3_3.stl" scale="0.001 0.001 0.001"/>
      </geometry>
      <origin rpy="0 0 3.1415" xyz="0 0 0"/>
      <material name="cframe">
        <color rgba="0.25 0.25 0.25 1"/>
      </material>
    </visual>
  </link>
  <link name="r_middle1_link">
    <visual>
      <geometry>
        <mesh filename="package://inmoov_meshes/meshes/middle3_1.stl" scale="0.001 0.001 0.001"/>
      </geometry>
      <origin rpy="0 0 3.1415" xyz="0 0 0"/>
      <material name="cframe">
        <color rgba="0.25 0.25 0.25 1"/>
      </material>
    </visual>
  </link>
  <link name="r_middle2_link">
    <visual>
      <geometry>
        <mesh filename="package://inmoov_meshes/meshes/middle3_2.stl" scale="0.001 0.001 0.001"/>
      </geometry>
      <origin rpy="0 0 3.1415" xyz="0 0 0"/>
      <material name="cframe">
        <color rgba="0.25 0.25 0.25 1"/>
      </material>
    </visual>
  </link>
  <link name="r_middle3_link">
    <visual>
      <geometry>
        <mesh filename="package://inmoov_meshes/meshes/middle3_3.stl" scale="0.001 0.001 0.001"/>
      </geometry>
      <origin rpy="0 0 3.1415" xyz="0 0 0"/>
      <material name="cframe">
        <color rgba="0.25 0.25 0.25 1"/>
      </material>
    </visual>
  </link>
  <link name="r_ring1_link">
    <visual>
      <geometry>
        <mesh filename="package://inmoov_meshes/meshes/r_ring3_1.stl" scale="0.001 0.001 0.001"/>
      </geometry>
      <origin rpy="0 0 3.1415" xyz="0 0 0"/>
      <material name="cframe">
        <color rgba="0.25 0.25 0.25 1"/>
      </material>
    </visual>
  </link>
  <link name="r_ring2_link">
    <visual>
      <geometry>
        <mesh filename="package://inmoov_meshes/meshes/ring3_2.stl" scale="0.001 0.001 0.001"/>
      </geometry>
      <origin rpy="0 0 3.1415" xyz="0 0 0"/>
      <material name="cframe">
        <color rgba="0.25 0.25 0.25 1"/>
      </material>
    </visual>
  </link>
  <link name="r_ring3_link">
    <visual>
      <geometry>
        <mesh filename="package://inmoov_meshes/meshes/ring3_3.stl" scale="0.001 0.001 0.001"/>
      </geometry>
      <origin rpy="0 0 3.1415" xyz="0 0 0"/>
      <material name="cframe">
        <color rgba="0.25 0.25 0.25 1"/>
      </material>
    </visual>
  </link>
  <link name="r_ring4_link">
    <visual>
      <geometry>
        <mesh filename="package://inmoov_meshes/meshes/ring3_4.stl" scale="0.001 0.001 0.001"/>
      </geometry>
      <origin rpy="0 0 3.1415" xyz="0 0 0"/>
      <material name="cframe">
        <color rgba="0.25 0.25 0.25 1"/>
      </material>
    </visual>
  </link>
  <link name="r_pinky1_link">
    <visual>
      <geometry>
        <mesh filename="package://inmoov_meshes/meshes/r_pinky3_1.stl" scale="0.001 0.001 0.001"/>
      </geometry>
      <origin rpy="0 0 3.1415" xyz="0 0 0"/>
      <material name="cframe">
        <color rgba="0.25 0.25 0.25 1"/>
      </material>
    </visual>
  </link>
  <link name="r_pinky2_link">
    <visual>
      <geometry>
        <mesh filename="package://inmoov_meshes/meshes/pinky3_2.stl" scale="0.001 0.001 0.001"/>
      </geometry>
      <origin rpy="0 0 3.1415" xyz="0 0 0"/>
      <material name="cframe">
        <color rgba="0.25 0.25 0.25 1"/>
      </material>
    </visual>
  </link>
  <link name="r_pinky3_link">
    <visual>
      <geometry>
        <mesh filename="package://inmoov_meshes/meshes/pinky3_3.stl" scale="0.001 0.001 0.001"/>
      </geometry>
      <origin rpy="0 0 3.1415" xyz="0 0 0"/>
      <material name="cframe">
        <color rgba="0.25 0.25 0.25 1"/>
      </material>
    </visual>
  </link>
  <link name="r_pinky4_link">
    <visual>
      <geometry>
        <mesh filename="package://inmoov_meshes/meshes/pinky3_4.stl" scale="0.001 0.001 0.001"/>
      </geometry>
      <origin rpy="0 0 3.1415" xyz="0 0 0"/>
      <material name="cframe">
        <color rgba="0.25 0.25 0.25 1"/>
      </material>
    </visual>
  </link>
  <joint name="r_thumb1_joint" type="revolute">
    <axis xyz="0 0 1"/>
    <limit effort="1000.0" lower="0" upper="1.57" velocity="0.5"/>
    <origin rpy="3.1415 0.1 0" xyz="-0.029 0 -0.0577"/>
    <mimic joint="r_thumb" multiplier="-0.75" offset="0"/>
    <parent link="r_hand_link"/>
    <child link="r_thumb1_link"/>
  </joint>
  <joint name="r_thumb_joint" type="revolute">
    <axis xyz="1 0 0"/>
    <limit effort="1000.0" lower="0" upper="1.5" velocity="0.5"/>
    <origin rpy="0 2.3 -0.3" xyz="-0.02725 -0.0006 0.014"/>
    <parent link="r_thumb1_link"/>
    <child link="r_thumb2_link"/>
  </joint>
  <joint name="r_thumb3_joint" type="revolute">
    <axis xyz="1 0 0"/>
    <limit effort="1000.0" lower="-1.57" upper="0" velocity="0.5"/>
    <origin rpy="0 0 0" xyz="0 0 -0.035"/>
    <mimic joint="r_thumb" multiplier="1" offset="0"/>
    <parent link="r_thumb2_link"/>
    <child link="r_thumb3_link"/>
  </joint>
  <joint name="r_index1_joint" type="revolute">
    <axis xyz="1 0 0"/>
    <limit effort="1000.0" lower="0" upper="1.5" velocity="0.5"/>
    <origin rpy="0 -0.1 3.1415" xyz="-0.0342 -0.0015 -0.119"/>
    <mimic joint="r_index" multiplier="1" offset="0"/>
    <parent link="r_hand_link"/>
    <child link="r_index1_link"/>
  </joint>
  <joint name="r_index_joint" type="revolute">
    <axis xyz="1 0 0"/>
    <limit effort="1000.0" lower="0" upper="1.5" velocity="0.5"/>
    <origin rpy="0 0 0" xyz="0 0.001 -0.03595"/>
    <parent link="r_index1_link"/>
    <child link="r_index2_link"/>
  </joint>
  <joint name="r_index3_joint" type="revolute">
    <axis xyz="1 0 0"/>
    <limit effort="1000.0" lower="0" upper="1.5" velocity="0.5"/>
    <origin rpy="0 0 0" xyz="0 0 -0.024"/>
    <mimic joint="r_index" multiplier="1" offset="0"/>
    <parent link="r_index2_link"/>
    <child link="r_index3_link"/>
  </joint>
  <joint name="r_middle1_joint" type="revolute">
    <axis xyz="1 0 0"/>
    <limit effort="1000.0" lower="0" upper="1.5" velocity="0.5"/>
    <origin rpy="0 0 3.1415" xyz="-0.007 -0.00175 -0.12325"/>
    <mimic joint="r_middle" multiplier="1" offset="0"/>
    <parent link="r_hand_link"/>
    <child link="r_middle1_link"/>
  </joint>
  <joint name="r_middle_joint" type="revolute">
    <axis xyz="1 0 0"/>
    <limit effort="1000.0" lower="0" upper="1.5" velocity="0.5"/>
    <origin rpy="0 0 0" xyz="0 0.000 -0.0389"/>
    <parent link="r_middle1_link"/>
    <child link="r_middle2_link"/>
  </joint>
  <joint name="r_middle3_joint" type="revolute">
    <axis xyz="1 0 0"/>
    <limit effort="1000.0" lower="-1.57" upper="0" velocity="0.5"/>
    <origin rpy="0 0 0" xyz="0 0.0005 -0.0259"/>
    <mimic joint="r_middle" multiplier="1" offset="0"/>
    <parent link="r_middle2_link"/>
    <child link="r_middle3_link"/>
  </joint>
  <joint name="r_ring1_joint" type="revolute">
    <axis xyz="0 0 1"/>
    <limit effort="1000.0" lower="-1.57" upper="0" velocity="0.5"/>
    <origin rpy="0 -0.7 3.1415" xyz="0.00705 0 -0.0794"/>
    <mimic joint="r_ring" multiplier="-0.1" offset="0"/>
    <parent link="r_hand_link"/>
    <child link="r_ring1_link"/>
  </joint>
  <joint name="r_ring_joint" type="revolute">
    <axis xyz="1 0 0"/>
    <limit effort="1000.0" lower="0" upper="1.5" velocity="0.5"/>
    <origin rpy="0 0.7775 0" xyz="-0.0351 0.00126 -0.0166"/>
    <parent link="r_ring1_link"/>
    <child link="r_ring2_link"/>
  </joint>
  <joint name="r_ring3_joint" type="revolute">
    <axis xyz="1 0 0"/>
    <limit effort="1000.0" lower="-1.57" upper="0" velocity="0.5"/>
    <origin rpy="0 0 0" xyz="0 0.0005 -0.0345"/>
    <mimic joint="r_ring" multiplier="1" offset="0"/>
    <parent link="r_ring2_link"/>
    <child link="r_ring3_link"/>
  </joint>
  <joint name="r_ring4_joint" type="revolute">
    <axis xyz="1 0 0"/>
    <limit effort="1000.0" lower="-1.57" upper="0" velocity="0.5"/>
    <origin rpy="0 0 0" xyz="0 0.0004 -0.0229"/>
    <mimic joint="r_ring" multiplier="1" offset="0"/>
    <parent link="r_ring3_link"/>
    <child link="r_ring4_link"/>
  </joint>
  <joint name="r_pinky1_joint" type="revolute">
    <axis xyz="0 0 1"/>
    <limit effort="1000.0" lower="-1.57" upper="0" velocity="0.5"/>
    <origin rpy="0 -0.7 3.1415" xyz="0.027 0 -0.0555"/>
    <mimic joint="r_pinky" multiplier="-0.1" offset="0"/>
    <parent link="r_hand_link"/>
    <child link="r_pinky1_link"/>
  </joint>
  <joint name="r_pinky_joint" type="revolute">
    <axis xyz="1 0 0"/>
    <limit effort="1000.0" lower="0" upper="1.5" velocity="0.5"/>
    <origin rpy="0 0.93 0" xyz="-0.046 -0 -0.0228"/>
    <parent link="r_pinky1_link"/>
    <child link="r_pinky2_link"/>
  </joint>
  <joint name="r_pinky3_joint" type="revolute">
    <axis xyz="1 0 0"/>
    <limit effort="1000.0" lower="-1.57" upper="0" velocity="0.5"/>
    <origin rpy="0 0 0" xyz="0 0.0005 -0.031"/>
    <mimic joint="r_pinky" multiplier="1" offset="0"/>
    <parent link="r_pinky2_link"/>
    <child link="r_pinky3_link"/>
  </joint>
  <joint name="r_pinky4_joint" type="revolute">
    <axis xyz="1 0 0"/>
    <limit effort="1000.0" lower="-1.57" upper="0" velocity="0.5"/>
    <origin rpy="0 0 0" xyz="0 0.0004 -0.0208"/>
    <mimic joint="r_pinky" multiplier="1" offset="0"/>
    <parent link="r_pinky3_link"/>
    <child link="r_pinky4_link"/>
  </joint>
  <link name="r_handcover_link">
    <visual>
      <geometry>
        <mesh filename="package://inmoov_meshes/meshes/r_cover_hand.stl" scale="0.001 0.001 0.001"/>
      </geometry>
      <origin rpy="0 0 0" xyz="0 0 0"/>
      <material name="ccover">
        <color rgba="0.6 0.6 0.6 1"/>
      </material>
    </visual>
  </link>
  <link name="r_cover_handring_link">
    <visual>
      <geometry>
        <mesh filename="package://inmoov_meshes/meshes/r_cover_handring.stl" scale="0.001 0.001 0.001"/>
      </geometry>
      <origin rpy="0 0 3.1415" xyz="0 0 0"/>
      <material name="ccover">
        <color rgba="0.6 0.6 0.6 1"/>
      </material>
    </visual>
  </link>
  <link name="r_cover_handpinky_link">
    <visual>
      <geometry>
        <mesh filename="package://inmoov_meshes/meshes/r_cover_handpinky.stl" scale="0.001 0.001 0.001"/>
      </geometry>
      <origin rpy="0 0 3.1415" xyz="0 0 0"/>
      <material name="ccover">
        <color rgba="0.6 0.6 0.6 1"/>
      </material>
    </visual>
  </link>
  <link name="r_cover_thumb_link">
    <visual>
      <geometry>
        <mesh filename="package://inmoov_meshes/meshes/r_cover_thumb.stl" scale="0.001 0.001 0.001"/>
      </geometry>
      <origin rpy="3.1415 0 0" xyz="0 0 0"/>
      <material name="ccover">
        <color rgba="0.6 0.6 0.6 1"/>
      </material>
    </visual>
  </link>
  <link name="r_cover_index_link">
    <visual>
      <geometry>
        <mesh filename="package://inmoov_meshes/meshes/r_cover_index.stl" scale="0.001 0.001 0.001"/>
      </geometry>
      <origin rpy="0 0 3.1415" xyz="0 0 0"/>
      <material name="ccover">
        <color rgba="0.6 0.6 0.6 1"/>
      </material>
    </visual>
  </link>
  <link name="r_cover_middle_link">
    <visual>
      <geometry>
        <mesh filename="package://inmoov_meshes/meshes/r_cover_middle.stl" scale="0.001 0.001 0.001"/>
      </geometry>
      <origin rpy="0 0 3.1415" xyz="0 0 0"/>
      <material name="ccover">
        <color rgba="0.6 0.6 0.6 1"/>
      </material>
    </visual>
  </link>
  <link name="r_cover_ring_link">
    <visual>
      <geometry>
        <mesh filename="package://inmoov_meshes/meshes/r_cover_ring.stl" scale="0.001 0.001 0.001"/>
      </geometry>
      <origin rpy="0 0 3.1415" xyz="0 0 0"/>
      <material name="ccover">
        <color rgba="0.6 0.6 0.6 1"/>
      </material>
    </visual>
  </link>
  <link name="r_cover_pinky_link">
    <visual>
      <geometry>
        <mesh filename="package://inmoov_meshes/meshes/r_cover_pinky.stl" scale="0.001 0.001 0.001"/>
      </geometry>
      <origin rpy="0 0 3.1415" xyz="0 0 0"/>
      <material name="ccover">
        <color rgba="0.6 0.6 0.6 1"/>
      </material>
    </visual>
  </link>
  <joint name="r_handcover_joint" type="fixed">
    <origin rpy="0 0 0" xyz="-0.0192 0.009 -0.0977"/>
    <parent link="r_hand_link"/>
    <child link="r_handcover_link"/>
  </joint>
  <joint name="r_cover_handring_joint" type="fixed">
    <origin rpy="0 0.7 0" xyz="-0.015 -0.009 -0.0008"/>
    <parent link="r_ring1_link"/>
    <child link="r_cover_handring_link"/>
  </joint>
  <joint name="r_cover_handpinky_joint" type="fixed">
    <origin rpy="0 0.7 0" xyz="-0.0205 -0.01 -0.0069"/>
    <parent link="r_pinky1_link"/>
    <child link="r_cover_handpinky_link"/>
  </joint>
  <joint name="r_cover_thumb_joint" type="fixed">
    <origin rpy="0 3.1 0" xyz="-0.02125 -0.01 -0.0047"/>
    <parent link="r_thumb1_link"/>
    <child link="r_cover_thumb_link"/>
  </joint>
  <joint name="r_cover_index_joint" type="fixed">
    <origin rpy="0.05 0 0" xyz="0 -0.0071 -0.012"/>
    <parent link="r_index1_link"/>
    <child link="r_cover_index_link"/>
  </joint>
  <joint name="r_cover_middle_joint" type="fixed">
    <origin rpy="-0.05 0 0" xyz="0 -0.0071 -0.012"/>
    <parent link="r_middle1_link"/>
    <child link="r_cover_middle_link"/>
  </joint>
  <joint name="r_cover_ring_joint" type="fixed">
    <origin rpy="-0.05 -0.1 0" xyz="0 -0.005 -0.011"/>
    <parent link="r_ring2_link"/>
    <child link="r_cover_ring_link"/>
  </joint>
  <joint name="r_cover_pinky_joint" type="fixed">
    <origin rpy="-0.05 -0.1 0" xyz="0 -0.005 -0.0105"/>
    <parent link="r_pinky2_link"/>
    <child link="r_cover_pinky_link"/>
  </joint>
  <joint name="base_to_hand_joint" type="revolute">
    <axis xyz="0 0 1"/>
    <limit effort="1000.0" lower="-3.14" upper="0" velocity="0.5"/>
    <origin rpy="0 3.1415 0" xyz="0 0 0"/>
    <parent link="base_link"/>
    <child link="r_hand_link"/>
  </joint>
</robot>

