<?xml version="1.0" ?>
<!-- =================================================================================== -->
<!-- |    This document was autogenerated by xacro from inmoov.urdf.xacro              | -->
<!-- |    EDITING THIS FILE BY HAND IS NOT RECOMMENDED                                 | -->
<!-- =================================================================================== -->
<robot name="inmoov" xmlns:xacro="http://ros.org/wiki/xacro">
  <link name="base_link">
    <visual>
      <geometry>
        <cylinder length="0.11" radius="0.26"/>
      </geometry>
      <origin rpy="0 0 0" xyz="0 0 0.055"/>
      <material name="cbase">
        <color rgba="0.1 0.1 0.1 1"/>
      </material>
    </visual>
  </link>
  <joint name="base_to_pedestal" type="fixed">
    <parent link="base_link"/>
    <child link="pedestal"/>
    <origin rpy="0 0 0" xyz="0 0 0"/>
  </joint>
  <link name="pedestal">
    <visual>
      <geometry>
        <cylinder length="0.94" radius="0.0254"/>
      </geometry>
      <origin rpy="0 0 0" xyz="0 0 0.58"/>
      <material name="cbase">
        <color rgba="0.1 0.1 0.1 1"/>
      </material>
    </visual>
  </link>
  <link name="head_tilt">
    <visual>
      <geometry>
        <mesh filename="package://inmoov_description/meshes/virtual.stl" scale="0.001 0.001 0.001"/>
      </geometry>
      <origin rpy="0 0 3.1415" xyz="0 0 0"/>
      <material name="cframe">
        <color rgba="0.25 0.25 0.25 1"/>
      </material>
    </visual>
  </link>
  <joint name="pedestal_to_mid_stomach" type="fixed">
    <parent link="pedestal"/>
    <child link="mid_stomach"/>
    <origin rpy="0 0 0" xyz="0 0 0"/>
  </joint>
  <link name="mid_stomach">
    <visual>
      <geometry>
        <mesh filename="package://inmoov_description/meshes/mid_stomach.stl" scale="0.001 0.001 0.001"/>
      </geometry>
      <origin rpy="0 0 0" xyz="0 0 1.152"/>
      <material name="cframe">
        <color rgba="0.25 0.25 0.25 1"/>
      </material>
    </visual>
  </link>
  <link name="disk">
    <visual>
      <geometry>
        <mesh filename="package://inmoov_description/meshes/disk.stl" scale="0.001 0.001 0.001"/>
      </geometry>
      <origin rpy="0 0 0" xyz="0 0 0"/>
      <material name="ccover">
        <color rgba="0.6 0.6 0.6 1"/>
      </material>
    </visual>
  </link>
  <link name="top_stomach">
    <visual>
      <geometry>
        <mesh filename="package://inmoov_description/meshes/top_stomach.stl" scale="0.001 0.001 0.001"/>
      </geometry>
      <origin rpy="0 0 0" xyz="0 0 0"/>
      <material name="cframe">
        <color rgba="0.25 0.25 0.25 1"/>
      </material>
    </visual>
  </link>
  <link name="torso">
    <visual>
      <geometry>
        <mesh filename="package://inmoov_description/meshes/torso.stl" scale="0.001 0.001 0.001"/>
      </geometry>
      <origin rpy="0 0 0" xyz="0 0 0"/>
      <material name="cframe">
        <color rgba="0.25 0.25 0.25 1"/>
      </material>
    </visual>
  </link>
  <link name="kinect2_link">
    <visual>
      <geometry>
        <mesh filename="package://inmoov_description/meshes/kinectone.stl" scale="0.001 0.001 0.001"/>
      </geometry>
      <origin rpy="1.57 0 0" xyz="0 0 0"/>
      <material name="ckinect">
        <color rgba="0.1 0.1 0.1 1"/>
      </material>
    </visual>
  </link>
  <link name="kinect2_ir_optical_frame">
    <visual>
      <geometry>
        <mesh filename="package://inmoov_description/meshes/kinectone.stl" scale="0.001 0.001 0.001"/>
      </geometry>
      <origin rpy="1.57 0 0" xyz="0 0 0"/>
      <material name="ckinect">
        <color rgba="0.1 0.1 0.1 1"/>
      </material>
    </visual>
  </link>
  <link name="kinect2_rgb_optical_frame">
    <visual>
      <geometry>
        <mesh filename="package://inmoov_description/meshes/kinectone.stl" scale="0.001 0.001 0.001"/>
      </geometry>
      <origin rpy="1.57 0 0" xyz="0 0 0"/>
      <material name="ckinect">
        <color rgba="0.1 0.1 0.1 1"/>
      </material>
    </visual>
  </link>
  <link name="chestplate">
    <visual>
      <geometry>
        <mesh filename="package://inmoov_description/meshes/chest.stl" scale="0.001 0.001 0.001"/>
      </geometry>
      <origin rpy="0 0 0" xyz="0 0 0"/>
      <material name="ccover">
        <color rgba="0.6 0.6 0.6 1"/>
      </material>
    </visual>
  </link>
  <joint name="waist_rotate" type="revolute">
    <axis xyz="0 0 1"/>
    <limit effort="1000.0" lower="-1.57" upper="1.57" velocity="0.5"/>
    <origin rpy="0 0 0" xyz="0 0 1.152"/>
    <parent link="mid_stomach"/>
    <child link="top_stomach"/>
  </joint>
  <joint name="disk" type="fixed">
    <origin rpy="0 0 0" xyz="0.046 0 0.09"/>
    <parent link="top_stomach"/>
    <child link="disk"/>
  </joint>
  <joint name="waist_lean" type="revolute">
    <axis xyz="1 0 0"/>
    <limit effort="1000.0" lower="-0.30" upper="0.30" velocity="0.5"/>
    <origin rpy="0 0 0" xyz="0 0 0.11"/>
    <parent link="top_stomach"/>
    <child link="torso"/>
  </joint>
  <joint name="chestplate" type="fixed">
    <origin rpy="0 0 0" xyz="0.039 0 0.025"/>
    <parent link="torso"/>
    <child link="chestplate"/>
  </joint>
  <joint name="kinect2" type="fixed">
    <origin rpy="-1.57 0 -1.57" xyz="0 0 0.066"/>
    <parent link="torso"/>
    <child link="kinect2_link"/>
  </joint>
  <joint name="kinect2_ir_optical_frame" type="fixed">
    <origin rpy="-1.57 0 -1.57" xyz="0 0 0.066"/>
    <parent link="torso"/>
    <child link="kinect2_ir_optical_frame"/>
  </joint>
  <joint name="kinect2_rgb_optical" type="fixed">
    <origin rpy="-1.57 0 -1.57" xyz="0 0 0.066"/>
    <parent link="torso"/>
    <child link="kinect2_rgb_optical_frame"/>
  </joint>
  <joint name="head_tilt" type="revolute">
    <axis xyz="1 0 0"/>
    <limit effort="1000.0" lower="0.30" upper="-0.30" velocity="0.5"/>
    <origin rpy="0 0 3.1415" xyz="-0.0315  -0.001 0.4551"/>
    <parent link="torso"/>
    <child link="head_tilt"/>
  </joint>
  <joint name="head_updown" type="revolute">
    <axis xyz="0 1 0"/>
    <limit effort="1000.0" lower="-0.30" upper="0.30" velocity="0.5"/>
    <origin rpy="0 0 3.1415" xyz="0 0 0"/>
    <parent link="head_tilt"/>
    <child link="head_base"/>
  </joint>
  <link name="head_base">
    <visual>
      <geometry>
        <mesh filename="package://inmoov_description/meshes/head_base.stl" scale="0.001 0.001 0.001"/>
      </geometry>
      <origin rpy="0 0 0" xyz="0 0 0"/>
      <material name="cframe">
        <color rgba="0.25 0.25 0.25 1"/>
      </material>
    </visual>
  </link>
  <link name="head">
    <visual>
      <geometry>
        <mesh filename="package://inmoov_description/meshes/head.stl" scale="0.001 0.001 0.001"/>
      </geometry>
      <origin rpy="0 0 0" xyz="0 0 0"/>
      <material name="cframe">
        <color rgba="0.25 0.25 0.25 1"/>
      </material>
    </visual>
  </link>
  <link name="jaw">
    <visual>
      <geometry>
        <mesh filename="package://inmoov_description/meshes/jaw.stl" scale="0.001 0.001 0.001"/>
      </geometry>
      <origin rpy="0 0 3.1415" xyz="0 0 0"/>
      <material name="ccover">
        <color rgba="0.6 0.6 0.6 1"/>
      </material>
    </visual>
  </link>
  <link name="skull">
    <visual>
      <geometry>
        <mesh filename="package://inmoov_description/meshes/skull.stl" scale="0.001 0.001 0.001"/>
      </geometry>
      <origin rpy="0 0 0" xyz="0 0 0"/>
      <material name="ccover">
        <color rgba="0.6 0.6 0.6 1"/>
      </material>
    </visual>
  </link>
  <link name="left_ear">
    <visual>
      <geometry>
        <mesh filename="package://inmoov_description/meshes/earleftv1.stl" scale="0.001 0.001 0.001"/>
      </geometry>
      <origin rpy="0 0 0" xyz="0 0 0"/>
      <material name="cframe">
        <color rgba="0.25 0.25 0.25 1"/>
      </material>
    </visual>
  </link>
  <link name="right_ear">
    <visual>
      <geometry>
        <mesh filename="package://inmoov_description/meshes/earrightv1.stl" scale="0.001 0.001 0.001"/>
      </geometry>
      <origin rpy="0 0 0" xyz="0 0 0"/>
      <material name="cframe">
        <color rgba="0.25 0.25 0.25 1"/>
      </material>
    </visual>
  </link>
  <joint name="head_leftright" type="revolute">
    <axis xyz="0 0 1"/>
    <limit effort="1000.0" lower="-1.57" upper="1.57" velocity="0.5"/>
    <origin rpy="0 0 0" xyz="0 0 0.0245"/>
    <parent link="head_base"/>
    <child link="head"/>
  </joint>
  <joint name="jaw" type="revolute">
    <axis xyz="1 0 0"/>
    <limit effort="1000.0" lower="0" upper="0.15" velocity="0.5"/>
    <origin rpy="0 -0.09 3.1415" xyz="0.0375 0.0005 0.0437"/>
    <parent link="head"/>
    <child link="jaw"/>
  </joint>
  <joint name="skull" type="fixed">
    <origin rpy="0 0 0" xyz="0.044 0 -0.0245"/>
    <parent link="head"/>
    <child link="skull"/>
  </joint>
  <joint name="left_ear" type="fixed">
    <origin rpy="0 0 0" xyz="0.035 0.056 0.0437"/>
    <parent link="head"/>
    <child link="left_ear"/>
  </joint>
  <joint name="right_ear" type="fixed">
    <origin rpy="0 0 0" xyz="0.035 -0.056 0.0437"/>
    <parent link="head"/>
    <child link="right_ear"/>
  </joint>
  <link name="face">
    <visual>
      <geometry>
        <mesh filename="package://inmoov_description/meshes/face.stl" scale="0.001 0.001 0.001"/>
      </geometry>
      <origin rpy="0 0 0" xyz="0 0 0"/>
      <material name="ccover">
        <color rgba="0.6 0.6 0.6 1"/>
      </material>
    </visual>
  </link>
  <joint name="eyes_updown" type="revolute">
    <axis xyz="0 1 0"/>
    <limit effort="1000.0" lower="-0.45" upper="0.45" velocity="0.5"/>
    <origin rpy="0 0 3.1415" xyz="0 0 0"/>
    <parent link="face"/>
    <child link="eyesupport"/>
  </joint>
  <link name="eyesupport">
    <visual>
      <geometry>
        <mesh filename="package://inmoov_description/meshes/eyesupport.stl" scale="0.001 0.001 0.001"/>
      </geometry>
      <origin rpy="0 0 3.1415" xyz="0 0 0"/>
      <material name="cframe">
        <color rgba="0.25 0.25 0.25 1"/>
      </material>
    </visual>
  </link>
  <link name="right_eyesupport">
    <visual>
      <geometry>
        <mesh filename="package://inmoov_description/meshes/right_eyesupport.stl" scale="0.001 0.001 0.001"/>
      </geometry>
      <origin rpy="0 0 0" xyz="0 0 0"/>
      <material name="cframe">
        <color rgba="0.25 0.25 0.25 1"/>
      </material>
    </visual>
  </link>
  <link name="right_camera">
    <visual>
      <geometry>
        <mesh filename="package://inmoov_description/meshes/camera.stl" scale="0.001 0.001 0.001"/>
      </geometry>
      <origin rpy="0 0 0" xyz="0 0 0"/>
      <material name="ccamera">
        <color rgba="0.1 0.1 0.1 1"/>
      </material>
    </visual>
  </link>
  <link name="right_eye">
    <visual>
      <geometry>
        <mesh filename="package://inmoov_description/meshes/eye.stl" scale="0.001 0.001 0.001"/>
      </geometry>
      <origin rpy="0 0 0" xyz="0 0 0"/>
      <material name="ceyeball">
        <color rgba="0.7 0.7 0.7 1"/>
      </material>
    </visual>
  </link>
  <link name="right_iris">
    <visual>
      <geometry>
        <mesh filename="package://inmoov_description/meshes/iris.stl" scale="0.001 0.001 0.001"/>
      </geometry>
      <origin rpy="0 0 0" xyz="0 0 0"/>
      <material name="ciris">
        <color rgba="0.25 0.41 0.88 1"/>
      </material>
    </visual>
  </link>
  <joint name="right_camera" type="fixed">
    <origin rpy="0 0 0" xyz="-0.001 0 0"/>
    <parent link="right_eyesupport"/>
    <child link="right_camera"/>
  </joint>
  <joint name="right_eye" type="fixed">
    <origin rpy="0 0 0" xyz="0.003 0 0"/>
    <parent link="right_eyesupport"/>
    <child link="right_eye"/>
  </joint>
  <joint name="right_iris" type="fixed">
    <origin rpy="0 0 0" xyz="0.0061 0 0"/>
    <parent link="right_eyesupport"/>
    <child link="right_iris"/>
  </joint>
  <joint name="eye_leftright" type="revolute">
    <axis xyz="0 0 1"/>
    <limit effort="1000.0" lower="-0.45" upper="0.45" velocity="0.5"/>
    <origin rpy="0 0 3.1415" xyz="0 0.033 -0.0036"/>
    <parent link="eyesupport"/>
    <child link="right_eyesupport"/>
  </joint>
  <link name="left_eyesupport">
    <visual>
      <geometry>
        <mesh filename="package://inmoov_description/meshes/left_eyesupport.stl" scale="0.001 0.001 0.001"/>
      </geometry>
      <origin rpy="0 0 0" xyz="0 0 0"/>
      <material name="cframe">
        <color rgba="0.25 0.25 0.25 1"/>
      </material>
    </visual>
  </link>
  <link name="left_camera">
    <visual>
      <geometry>
        <mesh filename="package://inmoov_description/meshes/camera.stl" scale="0.001 0.001 0.001"/>
      </geometry>
      <origin rpy="0 0 0" xyz="0 0 0"/>
      <material name="ccamera">
        <color rgba="0.1 0.1 0.1 1"/>
      </material>
    </visual>
  </link>
  <link name="left_eye">
    <visual>
      <geometry>
        <mesh filename="package://inmoov_description/meshes/eye.stl" scale="0.001 0.001 0.001"/>
      </geometry>
      <origin rpy="0 0 0" xyz="0 0 0"/>
      <material name="ceyeball">
        <color rgba="0.7 0.7 0.7 1"/>
      </material>
    </visual>
  </link>
  <link name="left_iris">
    <visual>
      <geometry>
        <mesh filename="package://inmoov_description/meshes/iris.stl" scale="0.001 0.001 0.001"/>
      </geometry>
      <origin rpy="0 0 0" xyz="0 0 0"/>
      <material name="ciris">
        <color rgba="0.25 0.41 0.88 1"/>
      </material>
    </visual>
  </link>
  <joint name="left_camera" type="fixed">
    <origin rpy="0 0 0" xyz="-0.001 0 0"/>
    <parent link="left_eyesupport"/>
    <child link="left_camera"/>
  </joint>
  <joint name="left_eye" type="fixed">
    <origin rpy="0 0 0" xyz="0.003 0 0"/>
    <parent link="left_eyesupport"/>
    <child link="left_eye"/>
  </joint>
  <joint name="left_iris" type="fixed">
    <origin rpy="0 0 0" xyz="0.0061 0 0"/>
    <parent link="left_eyesupport"/>
    <child link="left_iris"/>
  </joint>
  <joint name="left_eye_leftright" type="revolute">
    <axis xyz="0 0 1"/>
    <limit effort="1000.0" lower="-0.45" upper="0.45" velocity="0.5"/>
    <mimic joint="eye_leftright" multiplier="1" offset="0"/>
    <origin rpy="0 0 3.1415" xyz="0 -0.033 -0.0036"/>
    <parent link="eyesupport"/>
    <child link="left_eyesupport"/>
  </joint>
  <joint name="face" type="fixed">
    <origin rpy="0 0 0" xyz="0.0637 0 0.079"/>
    <parent link="skull"/>
    <child link="face"/>
  </joint>
  <link name="right_shoulder_base">
    <visual>
      <geometry>
        <mesh filename="package://inmoov_description/meshes/right_shoulder_base.stl" scale="0.001 0.001 0.001"/>
      </geometry>
      <origin rpy="0 0 3.14" xyz="0 0 0"/>
      <material name="cframe">
        <color rgba="0.25 0.25 0.25 1"/>
      </material>
    </visual>
  </link>
  <link name="right_shoulder">
    <visual>
      <geometry>
        <mesh filename="package://inmoov_description/meshes/right_shoulder.stl" scale="0.001 0.001 0.001"/>
      </geometry>
      <origin rpy="0 0 0" xyz="0 0 0"/>
      <material name="cframe">
        <color rgba="0.25 0.25 0.25 1"/>
      </material>
    </visual>
  </link>
  <link name="right_bicep">
    <visual>
      <geometry>
        <mesh filename="package://inmoov_description/meshes/bicep.stl" scale="0.001 0.001 0.001"/>
      </geometry>
      <origin rpy="0 3.14 0" xyz="0 0 0"/>
      <material name="cframe">
        <color rgba="0.25 0.25 0.25 1"/>
      </material>
    </visual>
  </link>
  <link name="right_bicepcover">
    <visual>
      <geometry>
        <mesh filename="package://inmoov_description/meshes/bicepcover.stl" scale="0.001 0.001 0.001"/>
      </geometry>
      <origin rpy="0 3.14 0" xyz="0 0 0"/>
      <material name="ccover">
        <color rgba="0.6 0.6 0.6 1"/>
      </material>
    </visual>
  </link>
  <link name="right_forearm">
    <visual>
      <geometry>
        <mesh filename="package://inmoov_description/meshes/right_forearm.stl" scale="0.001 0.001 0.001"/>
      </geometry>
      <origin rpy="0 0 0" xyz="0.001 0 0"/>
      <material name="ccover">
        <color rgba="0.6 0.6 0.6 1"/>
      </material>
    </visual>
  </link>
  <joint name="right_shoulder_up" type="revolute">
    <axis xyz="1 0 0"/>
    <limit effort="1000.0" lower="0" upper="3.14" velocity="0.5"/>
    <origin rpy="0 0 3.14" xyz="-0.012 0 -0.04"/>
    <parent link="right_shoulder_base"/>
    <child link="right_shoulder"/>
  </joint>
  <joint name="right_bicep_rotate" type="revolute">
    <axis xyz="0 0 1"/>
    <limit effort="1000.0" lower="-1.57" upper="1.57" velocity="0.5"/>
    <origin rpy="0 3.14 0" xyz="0.066 0 -0.060"/>
    <parent link="right_shoulder"/>
    <child link="right_bicep"/>
  </joint>
  <joint name="right_bicep" type="revolute">
    <axis xyz="1 0 0"/>
    <limit effort="1000.0" lower="0.4" upper="1.57" velocity="0.5"/>
    <origin rpy="0 3.14 0" xyz="0 -0.0278 0.2235"/>
    <parent link="right_bicep"/>
    <child link="right_forearm"/>
  </joint>
  <joint name="right_bicepcover" type="fixed">
    <origin rpy="0 0 0" xyz="0 0 0"/>
    <parent link="right_bicep"/>
    <child link="right_bicepcover"/>
  </joint>
  <joint name="right_shoulder_side" type="revolute">
    <axis xyz="0 1 0"/>
    <limit effort="1000.0" lower="0" upper="0.75" velocity="0.5"/>
    <origin rpy="0 0 1.57" xyz="0 -0.143 0.298"/>
    <parent link="torso"/>
    <child link="right_shoulder_base"/>
  </joint>
  <link name="right_hand">
    <visual>
      <geometry>
        <mesh filename="package://inmoov_description/meshes/right_hand.stl" scale="0.001 0.001 0.001"/>
      </geometry>
      <origin rpy="0 0 0" xyz="0 0 0"/>
      <material name="cframe">
        <color rgba="0.25 0.25 0.25 1"/>
      </material>
    </visual>
  </link>
  <link name="right_thumb1">
    <visual>
      <geometry>
        <mesh filename="package://inmoov_description/meshes/right_thumb5_1.stl" scale="0.001 0.001 0.001"/>
      </geometry>
      <origin rpy="3.1415 0 0" xyz="0 0 0"/>
      <material name="cframe">
        <color rgba="0.25 0.25 0.25 1"/>
      </material>
    </visual>
  </link>
  <link name="right_thumb2">
    <visual>
      <geometry>
        <mesh filename="package://inmoov_description/meshes/thumb5_2.stl" scale="0.001 0.001 0.001"/>
      </geometry>
      <origin rpy="0 0 3.1415" xyz="0 0 0"/>
      <material name="cframe">
        <color rgba="0.25 0.25 0.25 1"/>
      </material>
    </visual>
  </link>
  <link name="right_thumb3">
    <visual>
      <geometry>
        <mesh filename="package://inmoov_description/meshes/thumb5_3.stl" scale="0.001 0.001 0.001"/>
      </geometry>
      <origin rpy="0 0 3.1415" xyz="0 0 0"/>
      <material name="cframe">
        <color rgba="0.25 0.25 0.25 1"/>
      </material>
    </visual>
  </link>
  <link name="right_index1">
    <visual>
      <geometry>
        <mesh filename="package://inmoov_description/meshes/index3_1.stl" scale="0.001 0.001 0.001"/>
      </geometry>
      <origin rpy="0 0 3.1415" xyz="0 0 0"/>
      <material name="cframe">
        <color rgba="0.25 0.25 0.25 1"/>
      </material>
    </visual>
  </link>
  <link name="right_index2">
    <visual>
      <geometry>
        <mesh filename="package://inmoov_description/meshes/index3_2.stl" scale="0.001 0.001 0.001"/>
      </geometry>
      <origin rpy="0 0 3.1415" xyz="0 0 0"/>
      <material name="cframe">
        <color rgba="0.25 0.25 0.25 1"/>
      </material>
    </visual>
  </link>
  <link name="right_index3">
    <visual>
      <geometry>
        <mesh filename="package://inmoov_description/meshes/index3_3.stl" scale="0.001 0.001 0.001"/>
      </geometry>
      <origin rpy="0 0 3.1415" xyz="0 0 0"/>
      <material name="cframe">
        <color rgba="0.25 0.25 0.25 1"/>
      </material>
    </visual>
  </link>
  <link name="right_middle1">
    <visual>
      <geometry>
        <mesh filename="package://inmoov_description/meshes/middle3_1.stl" scale="0.001 0.001 0.001"/>
      </geometry>
      <origin rpy="0 0 3.1415" xyz="0 0 0"/>
      <material name="cframe">
        <color rgba="0.25 0.25 0.25 1"/>
      </material>
    </visual>
  </link>
  <link name="right_middle2">
    <visual>
      <geometry>
        <mesh filename="package://inmoov_description/meshes/middle3_2.stl" scale="0.001 0.001 0.001"/>
      </geometry>
      <origin rpy="0 0 3.1415" xyz="0 0 0"/>
      <material name="cframe">
        <color rgba="0.25 0.25 0.25 1"/>
      </material>
    </visual>
  </link>
  <link name="right_middle3">
    <visual>
      <geometry>
        <mesh filename="package://inmoov_description/meshes/middle3_3.stl" scale="0.001 0.001 0.001"/>
      </geometry>
      <origin rpy="0 0 3.1415" xyz="0 0 0"/>
      <material name="cframe">
        <color rgba="0.25 0.25 0.25 1"/>
      </material>
    </visual>
  </link>
  <link name="right_ring1">
    <visual>
      <geometry>
        <mesh filename="package://inmoov_description/meshes/right_ring3_1.stl" scale="0.001 0.001 0.001"/>
      </geometry>
      <origin rpy="0 0 3.1415" xyz="0 0 0"/>
      <material name="cframe">
        <color rgba="0.25 0.25 0.25 1"/>
      </material>
    </visual>
  </link>
  <link name="right_ring2">
    <visual>
      <geometry>
        <mesh filename="package://inmoov_description/meshes/ring3_2.stl" scale="0.001 0.001 0.001"/>
      </geometry>
      <origin rpy="0 0 3.1415" xyz="0 0 0"/>
      <material name="cframe">
        <color rgba="0.25 0.25 0.25 1"/>
      </material>
    </visual>
  </link>
  <link name="right_ring3">
    <visual>
      <geometry>
        <mesh filename="package://inmoov_description/meshes/ring3_3.stl" scale="0.001 0.001 0.001"/>
      </geometry>
      <origin rpy="0 0 3.1415" xyz="0 0 0"/>
      <material name="cframe">
        <color rgba="0.25 0.25 0.25 1"/>
      </material>
    </visual>
  </link>
  <link name="right_ring4">
    <visual>
      <geometry>
        <mesh filename="package://inmoov_description/meshes/ring3_4.stl" scale="0.001 0.001 0.001"/>
      </geometry>
      <origin rpy="0 0 3.1415" xyz="0 0 0"/>
      <material name="cframe">
        <color rgba="0.25 0.25 0.25 1"/>
      </material>
    </visual>
  </link>
  <link name="right_pinky1">
    <visual>
      <geometry>
        <mesh filename="package://inmoov_description/meshes/right_pinky3_1.stl" scale="0.001 0.001 0.001"/>
      </geometry>
      <origin rpy="0 0 3.1415" xyz="0 0 0"/>
      <material name="cframe">
        <color rgba="0.25 0.25 0.25 1"/>
      </material>
    </visual>
  </link>
  <link name="right_pinky2">
    <visual>
      <geometry>
        <mesh filename="package://inmoov_description/meshes/pinky3_2.stl" scale="0.001 0.001 0.001"/>
      </geometry>
      <origin rpy="0 0 3.1415" xyz="0 0 0"/>
      <material name="cframe">
        <color rgba="0.25 0.25 0.25 1"/>
      </material>
    </visual>
  </link>
  <link name="right_pinky3">
    <visual>
      <geometry>
        <mesh filename="package://inmoov_description/meshes/pinky3_3.stl" scale="0.001 0.001 0.001"/>
      </geometry>
      <origin rpy="0 0 3.1415" xyz="0 0 0"/>
      <material name="cframe">
        <color rgba="0.25 0.25 0.25 1"/>
      </material>
    </visual>
  </link>
  <link name="right_pinky4">
    <visual>
      <geometry>
        <mesh filename="package://inmoov_description/meshes/pinky3_4.stl" scale="0.001 0.001 0.001"/>
      </geometry>
      <origin rpy="0 0 3.1415" xyz="0 0 0"/>
      <material name="cframe">
        <color rgba="0.25 0.25 0.25 1"/>
      </material>
    </visual>
  </link>
  <joint name="right_thumb1" type="revolute">
    <axis xyz="0 0 1"/>
    <limit effort="1000.0" lower="0" upper="1.57" velocity="0.5"/>
    <origin rpy="3.1415 0.1 0" xyz="-0.029 0 -0.0577"/>
    <mimic joint="right_thumb" multiplier="-0.75" offset="0"/>
    <parent link="right_hand"/>
    <child link="right_thumb1"/>
  </joint>
  <joint name="right_thumb" type="revolute">
    <axis xyz="1 0 0"/>
    <limit effort="1000.0" lower="0" upper="1.5" velocity="0.5"/>
    <origin rpy="0 2.3 -0.3" xyz="-0.02725 -0.0006 0.014"/>
    <parent link="right_thumb1"/>
    <child link="right_thumb2"/>
  </joint>
  <joint name="right_thumb3" type="revolute">
    <axis xyz="1 0 0"/>
    <limit effort="1000.0" lower="-1.57" upper="0" velocity="0.5"/>
    <origin rpy="0 0 0" xyz="0 0 -0.035"/>
    <mimic joint="right_thumb" multiplier="1" offset="0"/>
    <parent link="right_thumb2"/>
    <child link="right_thumb3"/>
  </joint>
  <joint name="right_index1" type="revolute">
    <axis xyz="1 0 0"/>
    <limit effort="1000.0" lower="0" upper="1.5" velocity="0.5"/>
    <origin rpy="0 -0.1 3.1415" xyz="-0.0342 -0.0015 -0.119"/>
    <mimic joint="right_index" multiplier="1" offset="0"/>
    <parent link="right_hand"/>
    <child link="right_index1"/>
  </joint>
  <joint name="right_index" type="revolute">
    <axis xyz="1 0 0"/>
    <limit effort="1000.0" lower="0" upper="1.5" velocity="0.5"/>
    <origin rpy="0 0 0" xyz="0 0.001 -0.03595"/>
    <parent link="right_index1"/>
    <child link="right_index2"/>
  </joint>
  <joint name="right_index3" type="revolute">
    <axis xyz="1 0 0"/>
    <limit effort="1000.0" lower="0" upper="1.5" velocity="0.5"/>
    <origin rpy="0 0 0" xyz="0 0 -0.024"/>
    <mimic joint="right_index" multiplier="1" offset="0"/>
    <parent link="right_index2"/>
    <child link="right_index3"/>
  </joint>
  <joint name="right_middle1" type="revolute">
    <axis xyz="1 0 0"/>
    <limit effort="1000.0" lower="0" upper="1.5" velocity="0.5"/>
    <origin rpy="0 0 3.1415" xyz="-0.007 -0.00175 -0.12325"/>
    <mimic joint="right_middle" multiplier="1" offset="0"/>
    <parent link="right_hand"/>
    <child link="right_middle1"/>
  </joint>
  <joint name="right_middle" type="revolute">
    <axis xyz="1 0 0"/>
    <limit effort="1000.0" lower="0" upper="1.5" velocity="0.5"/>
    <origin rpy="0 0 0" xyz="0 0.000 -0.0389"/>
    <parent link="right_middle1"/>
    <child link="right_middle2"/>
  </joint>
  <joint name="right_middle3" type="revolute">
    <axis xyz="1 0 0"/>
    <limit effort="1000.0" lower="-1.57" upper="0" velocity="0.5"/>
    <origin rpy="0 0 0" xyz="0 0.0005 -0.0259"/>
    <mimic joint="right_middle" multiplier="1" offset="0"/>
    <parent link="right_middle2"/>
    <child link="right_middle3"/>
  </joint>
  <joint name="right_ring1" type="revolute">
    <axis xyz="0 0 1"/>
    <limit effort="1000.0" lower="-1.57" upper="0" velocity="0.5"/>
    <origin rpy="0 -0.7 3.1415" xyz="0.00705 0 -0.0794"/>
    <mimic joint="right_ring" multiplier="-0.1" offset="0"/>
    <parent link="right_hand"/>
    <child link="right_ring1"/>
  </joint>
  <joint name="right_ring" type="revolute">
    <axis xyz="1 0 0"/>
    <limit effort="1000.0" lower="0" upper="1.5" velocity="0.5"/>
    <origin rpy="0 0.7775 0" xyz="-0.0351 0.00126 -0.0166"/>
    <parent link="right_ring1"/>
    <child link="right_ring2"/>
  </joint>
  <joint name="right_ring3" type="revolute">
    <axis xyz="1 0 0"/>
    <limit effort="1000.0" lower="-1.57" upper="0" velocity="0.5"/>
    <origin rpy="0 0 0" xyz="0 0.0005 -0.0345"/>
    <mimic joint="right_ring" multiplier="1" offset="0"/>
    <parent link="right_ring2"/>
    <child link="right_ring3"/>
  </joint>
  <joint name="right_ring4" type="revolute">
    <axis xyz="1 0 0"/>
    <limit effort="1000.0" lower="-1.57" upper="0" velocity="0.5"/>
    <origin rpy="0 0 0" xyz="0 0.0004 -0.0229"/>
    <mimic joint="right_ring" multiplier="1" offset="0"/>
    <parent link="right_ring3"/>
    <child link="right_ring4"/>
  </joint>
  <joint name="right_pinky1" type="revolute">
    <axis xyz="0 0 1"/>
    <limit effort="1000.0" lower="-1.57" upper="0" velocity="0.5"/>
    <origin rpy="0 -0.7 3.1415" xyz="0.027 0 -0.0555"/>
    <mimic joint="right_pinky" multiplier="-0.1" offset="0"/>
    <parent link="right_hand"/>
    <child link="right_pinky1"/>
  </joint>
  <joint name="right_pinky" type="revolute">
    <axis xyz="1 0 0"/>
    <limit effort="1000.0" lower="0" upper="1.5" velocity="0.5"/>
    <origin rpy="0 0.93 0" xyz="-0.046 -0 -0.0228"/>
    <parent link="right_pinky1"/>
    <child link="right_pinky2"/>
  </joint>
  <joint name="right_pinky3" type="revolute">
    <axis xyz="1 0 0"/>
    <limit effort="1000.0" lower="-1.57" upper="0" velocity="0.5"/>
    <origin rpy="0 0 0" xyz="0 0.0005 -0.031"/>
    <mimic joint="right_pinky" multiplier="1" offset="0"/>
    <parent link="right_pinky2"/>
    <child link="right_pinky3"/>
  </joint>
  <joint name="right_pinky4" type="revolute">
    <axis xyz="1 0 0"/>
    <limit effort="1000.0" lower="-1.57" upper="0" velocity="0.5"/>
    <origin rpy="0 0 0" xyz="0 0.0004 -0.0208"/>
    <mimic joint="right_pinky" multiplier="1" offset="0"/>
    <parent link="right_pinky3"/>
    <child link="right_pinky4"/>
  </joint>
  <link name="right_handcover">
    <visual>
      <geometry>
        <mesh filename="package://inmoov_description/meshes/right_cover_hand.stl" scale="0.001 0.001 0.001"/>
      </geometry>
      <origin rpy="0 0 0" xyz="0 0 0"/>
      <material name="ccover">
        <color rgba="0.6 0.6 0.6 1"/>
      </material>
    </visual>
  </link>
  <link name="right_cover_handring">
    <visual>
      <geometry>
        <mesh filename="package://inmoov_description/meshes/right_cover_handring.stl" scale="0.001 0.001 0.001"/>
      </geometry>
      <origin rpy="0 0 3.1415" xyz="0 0 0"/>
      <material name="ccover">
        <color rgba="0.6 0.6 0.6 1"/>
      </material>
    </visual>
  </link>
  <link name="right_cover_handpinky">
    <visual>
      <geometry>
        <mesh filename="package://inmoov_description/meshes/right_cover_handpinky.stl" scale="0.001 0.001 0.001"/>
      </geometry>
      <origin rpy="0 0 3.1415" xyz="0 0 0"/>
      <material name="ccover">
        <color rgba="0.6 0.6 0.6 1"/>
      </material>
    </visual>
  </link>
  <link name="right_cover_thumb">
    <visual>
      <geometry>
        <mesh filename="package://inmoov_description/meshes/right_cover_thumb.stl" scale="0.001 0.001 0.001"/>
      </geometry>
      <origin rpy="3.1415 0 0" xyz="0 0 0"/>
      <material name="ccover">
        <color rgba="0.6 0.6 0.6 1"/>
      </material>
    </visual>
  </link>
  <link name="right_cover_index">
    <visual>
      <geometry>
        <mesh filename="package://inmoov_description/meshes/right_cover_index.stl" scale="0.001 0.001 0.001"/>
      </geometry>
      <origin rpy="0 0 3.1415" xyz="0 0 0"/>
      <material name="ccover">
        <color rgba="0.6 0.6 0.6 1"/>
      </material>
    </visual>
  </link>
  <link name="right_cover_middle">
    <visual>
      <geometry>
        <mesh filename="package://inmoov_description/meshes/right_cover_middle.stl" scale="0.001 0.001 0.001"/>
      </geometry>
      <origin rpy="0 0 3.1415" xyz="0 0 0"/>
      <material name="ccover">
        <color rgba="0.6 0.6 0.6 1"/>
      </material>
    </visual>
  </link>
  <link name="right_cover_ring">
    <visual>
      <geometry>
        <mesh filename="package://inmoov_description/meshes/right_cover_ring.stl" scale="0.001 0.001 0.001"/>
      </geometry>
      <origin rpy="0 0 3.1415" xyz="0 0 0"/>
      <material name="ccover">
        <color rgba="0.6 0.6 0.6 1"/>
      </material>
    </visual>
  </link>
  <link name="right_cover_pinky">
    <visual>
      <geometry>
        <mesh filename="package://inmoov_description/meshes/right_cover_pinky.stl" scale="0.001 0.001 0.001"/>
      </geometry>
      <origin rpy="0 0 3.1415" xyz="0 0 0"/>
      <material name="ccover">
        <color rgba="0.6 0.6 0.6 1"/>
      </material>
    </visual>
  </link>
  <joint name="right_handcover" type="fixed">
    <origin rpy="0 0 0" xyz="-0.0192 0.009 -0.0977"/>
    <parent link="right_hand"/>
    <child link="right_handcover"/>
  </joint>
  <joint name="right_cover_handring" type="fixed">
    <origin rpy="0 0.7 0" xyz="-0.015 -0.009 -0.0008"/>
    <parent link="right_ring1"/>
    <child link="right_cover_handring"/>
  </joint>
  <joint name="right_cover_handpinky" type="fixed">
    <origin rpy="0 0.7 0" xyz="-0.0205 -0.01 -0.0069"/>
    <parent link="right_pinky1"/>
    <child link="right_cover_handpinky"/>
  </joint>
  <joint name="right_cover_thumb" type="fixed">
    <origin rpy="0 3.1 0" xyz="-0.02125 -0.01 -0.0047"/>
    <parent link="right_thumb1"/>
    <child link="right_cover_thumb"/>
  </joint>
  <joint name="right_cover_index" type="fixed">
    <origin rpy="0.05 0 0" xyz="0 -0.0071 -0.012"/>
    <parent link="right_index1"/>
    <child link="right_cover_index"/>
  </joint>
  <joint name="right_cover_middle" type="fixed">
    <origin rpy="-0.05 0 0" xyz="0 -0.0071 -0.012"/>
    <parent link="right_middle1"/>
    <child link="right_cover_middle"/>
  </joint>
  <joint name="right_cover_ring" type="fixed">
    <origin rpy="-0.05 -0.1 0" xyz="0 -0.005 -0.011"/>
    <parent link="right_ring2"/>
    <child link="right_cover_ring"/>
  </joint>
  <joint name="right_cover_pinky" type="fixed">
    <origin rpy="-0.05 -0.1 0" xyz="0 -0.005 -0.0105"/>
    <parent link="right_pinky2"/>
    <child link="right_cover_pinky"/>
  </joint>
  <joint name="right_hand" type="revolute">
    <axis xyz="0 0 1"/>
    <limit effort="1000.0" lower="-3.14" upper="0" velocity="0.5"/>
    <origin rpy="0 0 0" xyz="-0.01 -0.0144 -0.2885"/>
    <parent link="right_forearm"/>
    <child link="right_hand"/>
  </joint>
  <link name="left_shoulder_base">
    <visual>
      <geometry>
        <mesh filename="package://inmoov_description/meshes/left_shoulder_base.stl" scale="0.001 0.001 0.001"/>
      </geometry>
      <origin rpy="0 0 0.0" xyz="0 0 0"/>
      <material name="cframe">
        <color rgba="0.25 0.25 0.25 1"/>
      </material>
    </visual>
  </link>
  <link name="left_shoulder">
    <visual>
      <geometry>
        <mesh filename="package://inmoov_description/meshes/left_shoulder.stl" scale="0.001 0.001 0.001"/>
      </geometry>
      <origin rpy="0 0 0" xyz="0 0 0"/>
      <material name="cframe">
        <color rgba="0.25 0.25 0.25 1"/>
      </material>
    </visual>
  </link>
  <link name="left_bicep">
    <visual>
      <geometry>
        <mesh filename="package://inmoov_description/meshes/bicep.stl" scale="0.001 0.001 0.001"/>
      </geometry>
      <origin rpy="0 0.0 0" xyz="0 0 0"/>
      <material name="cframe">
        <color rgba="0.25 0.25 0.25 1"/>
      </material>
    </visual>
  </link>
  <link name="left_bicepcover">
    <visual>
      <geometry>
        <mesh filename="package://inmoov_description/meshes/bicepcover.stl" scale="0.001 0.001 0.001"/>
      </geometry>
      <origin rpy="0 0.0 0" xyz="0 0 0"/>
      <material name="ccover">
        <color rgba="0.6 0.6 0.6 1"/>
      </material>
    </visual>
  </link>
  <link name="left_forearm">
    <visual>
      <geometry>
        <mesh filename="package://inmoov_description/meshes/left_forearm.stl" scale="0.001 0.001 0.001"/>
      </geometry>
      <origin rpy="0 0 0" xyz="-0.001 0 0"/>
      <material name="ccover">
        <color rgba="0.6 0.6 0.6 1"/>
      </material>
    </visual>
  </link>
  <joint name="left_shoulder_up" type="revolute">
    <axis xyz="1 0 0"/>
    <limit effort="1000.0" lower="0" upper="3.14" velocity="0.5"/>
    <origin rpy="0 0 0.0" xyz="-0.012 0 -0.04"/>
    <parent link="left_shoulder_base"/>
    <child link="left_shoulder"/>
  </joint>
  <joint name="left_bicep_rotate" type="revolute">
    <axis xyz="0 0 1"/>
    <limit effort="1000.0" lower="-1.57" upper="1.57" velocity="0.5"/>
    <origin rpy="0 0.0 0" xyz="-0.066 0 -0.060"/>
    <parent link="left_shoulder"/>
    <child link="left_bicep"/>
  </joint>
  <joint name="left_bicep" type="revolute">
    <axis xyz="1 0 0"/>
    <limit effort="1000.0" lower="0.4" upper="1.57" velocity="0.5"/>
    <origin rpy="0 0.0 0" xyz="0 -0.0278 -0.2235"/>
    <parent link="left_bicep"/>
    <child link="left_forearm"/>
  </joint>
  <joint name="left_bicepcover" type="fixed">
    <origin rpy="0 0 0" xyz="0 0 0"/>
    <parent link="left_bicep"/>
    <child link="left_bicepcover"/>
  </joint>
  <joint name="left_shoulder_side" type="revolute">
    <axis xyz="0 1 0"/>
    <limit effort="1000.0" lower="0" upper="0.75" velocity="0.5"/>
    <origin rpy="0 0 -1.57" xyz="0 0.143 0.298"/>
    <parent link="torso"/>
    <child link="left_shoulder_base"/>
  </joint>
  <link name="left_hand">
    <visual>
      <geometry>
        <mesh filename="package://inmoov_description/meshes/left_hand.stl" scale="0.001 0.001 0.001"/>
      </geometry>
      <origin rpy="0 0 0" xyz="0 0 0"/>
      <material name="cframe">
        <color rgba="0.25 0.25 0.25 1"/>
      </material>
    </visual>
  </link>
  <link name="left_thumb1">
    <visual>
      <geometry>
        <mesh filename="package://inmoov_description/meshes/left_thumb5_1.stl" scale="0.001 0.001 0.001"/>
      </geometry>
      <origin rpy="3.1415 0 0" xyz="0 0 0"/>
      <material name="cframe">
        <color rgba="0.25 0.25 0.25 1"/>
      </material>
    </visual>
  </link>
  <link name="left_thumb2">
    <visual>
      <geometry>
        <mesh filename="package://inmoov_description/meshes/thumb5_2.stl" scale="0.001 0.001 0.001"/>
      </geometry>
      <origin rpy="0 0 3.1415" xyz="0 0 0"/>
      <material name="cframe">
        <color rgba="0.25 0.25 0.25 1"/>
      </material>
    </visual>
  </link>
  <link name="left_thumb3">
    <visual>
      <geometry>
        <mesh filename="package://inmoov_description/meshes/thumb5_3.stl" scale="0.001 0.001 0.001"/>
      </geometry>
      <origin rpy="0 0 3.1415" xyz="0 0 0"/>
      <material name="cframe">
        <color rgba="0.25 0.25 0.25 1"/>
      </material>
    </visual>
  </link>
  <link name="left_index1">
    <visual>
      <geometry>
        <mesh filename="package://inmoov_description/meshes/index3_1.stl" scale="0.001 0.001 0.001"/>
      </geometry>
      <origin rpy="0 0 3.1415" xyz="0 0 0"/>
      <material name="cframe">
        <color rgba="0.25 0.25 0.25 1"/>
      </material>
    </visual>
  </link>
  <link name="left_index2">
    <visual>
      <geometry>
        <mesh filename="package://inmoov_description/meshes/index3_2.stl" scale="0.001 0.001 0.001"/>
      </geometry>
      <origin rpy="0 0 3.1415" xyz="0 0 0"/>
      <material name="cframe">
        <color rgba="0.25 0.25 0.25 1"/>
      </material>
    </visual>
  </link>
  <link name="left_index3">
    <visual>
      <geometry>
        <mesh filename="package://inmoov_description/meshes/index3_3.stl" scale="0.001 0.001 0.001"/>
      </geometry>
      <origin rpy="0 0 3.1415" xyz="0 0 0"/>
      <material name="cframe">
        <color rgba="0.25 0.25 0.25 1"/>
      </material>
    </visual>
  </link>
  <link name="left_middle1">
    <visual>
      <geometry>
        <mesh filename="package://inmoov_description/meshes/middle3_1.stl" scale="0.001 0.001 0.001"/>
      </geometry>
      <origin rpy="0 0 3.1415" xyz="0 0 0"/>
      <material name="cframe">
        <color rgba="0.25 0.25 0.25 1"/>
      </material>
    </visual>
  </link>
  <link name="left_middle2">
    <visual>
      <geometry>
        <mesh filename="package://inmoov_description/meshes/middle3_2.stl" scale="0.001 0.001 0.001"/>
      </geometry>
      <origin rpy="0 0 3.1415" xyz="0 0 0"/>
      <material name="cframe">
        <color rgba="0.25 0.25 0.25 1"/>
      </material>
    </visual>
  </link>
  <link name="left_middle3">
    <visual>
      <geometry>
        <mesh filename="package://inmoov_description/meshes/middle3_3.stl" scale="0.001 0.001 0.001"/>
      </geometry>
      <origin rpy="0 0 3.1415" xyz="0 0 0"/>
      <material name="cframe">
        <color rgba="0.25 0.25 0.25 1"/>
      </material>
    </visual>
  </link>
  <link name="left_ring1">
    <visual>
      <geometry>
        <mesh filename="package://inmoov_description/meshes/left_ring3_1.stl" scale="0.001 0.001 0.001"/>
      </geometry>
      <origin rpy="0 0 3.1415" xyz="0 0 0"/>
      <material name="cframe">
        <color rgba="0.25 0.25 0.25 1"/>
      </material>
    </visual>
  </link>
  <link name="left_ring2">
    <visual>
      <geometry>
        <mesh filename="package://inmoov_description/meshes/ring3_2.stl" scale="0.001 0.001 0.001"/>
      </geometry>
      <origin rpy="0 0 3.1415" xyz="0 0 0"/>
      <material name="cframe">
        <color rgba="0.25 0.25 0.25 1"/>
      </material>
    </visual>
  </link>
  <link name="left_ring3">
    <visual>
      <geometry>
        <mesh filename="package://inmoov_description/meshes/ring3_3.stl" scale="0.001 0.001 0.001"/>
      </geometry>
      <origin rpy="0 0 3.1415" xyz="0 0 0"/>
      <material name="cframe">
        <color rgba="0.25 0.25 0.25 1"/>
      </material>
    </visual>
  </link>
  <link name="left_ring4">
    <visual>
      <geometry>
        <mesh filename="package://inmoov_description/meshes/ring3_4.stl" scale="0.001 0.001 0.001"/>
      </geometry>
      <origin rpy="0 0 3.1415" xyz="0 0 0"/>
      <material name="cframe">
        <color rgba="0.25 0.25 0.25 1"/>
      </material>
    </visual>
  </link>
  <link name="left_pinky1">
    <visual>
      <geometry>
        <mesh filename="package://inmoov_description/meshes/left_pinky3_1.stl" scale="0.001 0.001 0.001"/>
      </geometry>
      <origin rpy="0 0 3.1415" xyz="0 0 0"/>
      <material name="cframe">
        <color rgba="0.25 0.25 0.25 1"/>
      </material>
    </visual>
  </link>
  <link name="left_pinky2">
    <visual>
      <geometry>
        <mesh filename="package://inmoov_description/meshes/pinky3_2.stl" scale="0.001 0.001 0.001"/>
      </geometry>
      <origin rpy="0 0 3.1415" xyz="0 0 0"/>
      <material name="cframe">
        <color rgba="0.25 0.25 0.25 1"/>
      </material>
    </visual>
  </link>
  <link name="left_pinky3">
    <visual>
      <geometry>
        <mesh filename="package://inmoov_description/meshes/pinky3_3.stl" scale="0.001 0.001 0.001"/>
      </geometry>
      <origin rpy="0 0 3.1415" xyz="0 0 0"/>
      <material name="cframe">
        <color rgba="0.25 0.25 0.25 1"/>
      </material>
    </visual>
  </link>
  <link name="left_pinky4">
    <visual>
      <geometry>
        <mesh filename="package://inmoov_description/meshes/pinky3_4.stl" scale="0.001 0.001 0.001"/>
      </geometry>
      <origin rpy="0 0 3.1415" xyz="0 0 0"/>
      <material name="cframe">
        <color rgba="0.25 0.25 0.25 1"/>
      </material>
    </visual>
  </link>
  <joint name="left_thumb1" type="revolute">
    <axis xyz="0 0 1"/>
    <limit effort="1000.0" lower="0" upper="-1.57" velocity="0.5"/>
    <origin rpy="3.1415 -0.1 0" xyz="0.029 0 -0.0577"/>
    <mimic joint="left_thumb" multiplier="0.75" offset="0"/>
    <parent link="left_hand"/>
    <child link="left_thumb1"/>
  </joint>
  <joint name="left_thumb" type="revolute">
    <axis xyz="1 0 0"/>
    <limit effort="1000.0" lower="0" upper="1.5" velocity="0.5"/>
    <origin rpy="0 -2.3 0.3" xyz="0.02725 -0.0006 0.014"/>
    <parent link="left_thumb1"/>
    <child link="left_thumb2"/>
  </joint>
  <joint name="left_thumb3" type="revolute">
    <axis xyz="1 0 0"/>
    <limit effort="1000.0" lower="-1.57" upper="0" velocity="0.5"/>
    <origin rpy="0 0 0" xyz="0 0 -0.035"/>
    <mimic joint="left_thumb" multiplier="1" offset="0"/>
    <parent link="left_thumb2"/>
    <child link="left_thumb3"/>
  </joint>
  <joint name="left_index1" type="revolute">
    <axis xyz="1 0 0"/>
    <limit effort="1000.0" lower="0" upper="1.5" velocity="0.5"/>
    <origin rpy="0 0.1 3.1415" xyz="0.0342 -0.0015 -0.119"/>
    <mimic joint="left_index" multiplier="1" offset="0"/>
    <parent link="left_hand"/>
    <child link="left_index1"/>
  </joint>
  <joint name="left_index" type="revolute">
    <axis xyz="1 0 0"/>
    <limit effort="1000.0" lower="0" upper="1.5" velocity="0.5"/>
    <origin rpy="0 0 0" xyz="0 0.001 -0.03595"/>
    <parent link="left_index1"/>
    <child link="left_index2"/>
  </joint>
  <joint name="left_index3" type="revolute">
    <axis xyz="1 0 0"/>
    <limit effort="1000.0" lower="0" upper="1.5" velocity="0.5"/>
    <origin rpy="0 0 0" xyz="0 0 -0.024"/>
    <mimic joint="left_index" multiplier="1" offset="0"/>
    <parent link="left_index2"/>
    <child link="left_index3"/>
  </joint>
  <joint name="left_middle1" type="revolute">
    <axis xyz="1 0 0"/>
    <limit effort="1000.0" lower="0" upper="1.5" velocity="0.5"/>
    <origin rpy="0 0 3.1415" xyz="0.007 -0.00175 -0.12325"/>
    <mimic joint="left_middle" multiplier="1" offset="0"/>
    <parent link="left_hand"/>
    <child link="left_middle1"/>
  </joint>
  <joint name="left_middle" type="revolute">
    <axis xyz="1 0 0"/>
    <limit effort="1000.0" lower="0" upper="1.5" velocity="0.5"/>
    <origin rpy="0 0 0" xyz="0 0.000 -0.0389"/>
    <parent link="left_middle1"/>
    <child link="left_middle2"/>
  </joint>
  <joint name="left_middle3" type="revolute">
    <axis xyz="1 0 0"/>
    <limit effort="1000.0" lower="-1.57" upper="0" velocity="0.5"/>
    <origin rpy="0 0 0" xyz="0 0.0005 -0.0259"/>
    <mimic joint="left_middle" multiplier="1" offset="0"/>
    <parent link="left_middle2"/>
    <child link="left_middle3"/>
  </joint>
  <joint name="left_ring1" type="revolute">
    <axis xyz="0 0 1"/>
    <limit effort="1000.0" lower="1.57" upper="0" velocity="0.5"/>
    <origin rpy="0 0.7 3.1415" xyz="-0.00705 0 -0.0794"/>
    <mimic joint="left_ring" multiplier="0.1" offset="0"/>
    <parent link="left_hand"/>
    <child link="left_ring1"/>
  </joint>
  <joint name="left_ring" type="revolute">
    <axis xyz="1 0 0"/>
    <limit effort="1000.0" lower="0" upper="1.5" velocity="0.5"/>
    <origin rpy="0 -0.7775 0" xyz="0.0351 0.00126 -0.0166"/>
    <parent link="left_ring1"/>
    <child link="left_ring2"/>
  </joint>
  <joint name="left_ring3" type="revolute">
    <axis xyz="1 0 0"/>
    <limit effort="1000.0" lower="-1.57" upper="0" velocity="0.5"/>
    <origin rpy="0 0 0" xyz="0 0.0005 -0.0345"/>
    <mimic joint="left_ring" multiplier="1" offset="0"/>
    <parent link="left_ring2"/>
    <child link="left_ring3"/>
  </joint>
  <joint name="left_ring4" type="revolute">
    <axis xyz="1 0 0"/>
    <limit effort="1000.0" lower="-1.57" upper="0" velocity="0.5"/>
    <origin rpy="0 0 0" xyz="0 0.0004 -0.0229"/>
    <mimic joint="left_ring" multiplier="1" offset="0"/>
    <parent link="left_ring3"/>
    <child link="left_ring4"/>
  </joint>
  <joint name="left_pinky1" type="revolute">
    <axis xyz="0 0 1"/>
    <limit effort="1000.0" lower="1.57" upper="0" velocity="0.5"/>
    <origin rpy="0 0.7 3.1415" xyz="-0.027 0 -0.0555"/>
    <mimic joint="left_pinky" multiplier="0.1" offset="0"/>
    <parent link="left_hand"/>
    <child link="left_pinky1"/>
  </joint>
  <joint name="left_pinky" type="revolute">
    <axis xyz="1 0 0"/>
    <limit effort="1000.0" lower="0" upper="1.5" velocity="0.5"/>
    <origin rpy="0 -0.93 0" xyz="0.046 -0 -0.0228"/>
    <parent link="left_pinky1"/>
    <child link="left_pinky2"/>
  </joint>
  <joint name="left_pinky3" type="revolute">
    <axis xyz="1 0 0"/>
    <limit effort="1000.0" lower="-1.57" upper="0" velocity="0.5"/>
    <origin rpy="0 0 0" xyz="0 0.0005 -0.031"/>
    <mimic joint="left_pinky" multiplier="1" offset="0"/>
    <parent link="left_pinky2"/>
    <child link="left_pinky3"/>
  </joint>
  <joint name="left_pinky4" type="revolute">
    <axis xyz="1 0 0"/>
    <limit effort="1000.0" lower="-1.57" upper="0" velocity="0.5"/>
    <origin rpy="0 0 0" xyz="0 0.0004 -0.0208"/>
    <mimic joint="left_pinky" multiplier="1" offset="0"/>
    <parent link="left_pinky3"/>
    <child link="left_pinky4"/>
  </joint>
  <link name="left_handcover">
    <visual>
      <geometry>
        <mesh filename="package://inmoov_description/meshes/left_cover_hand.stl" scale="0.001 0.001 0.001"/>
      </geometry>
      <origin rpy="0 0 0" xyz="0 0 0"/>
      <material name="ccover">
        <color rgba="0.6 0.6 0.6 1"/>
      </material>
    </visual>
  </link>
  <link name="left_cover_handring">
    <visual>
      <geometry>
        <mesh filename="package://inmoov_description/meshes/left_cover_handring.stl" scale="0.001 0.001 0.001"/>
      </geometry>
      <origin rpy="0 0 3.1415" xyz="0 0 0"/>
      <material name="ccover">
        <color rgba="0.6 0.6 0.6 1"/>
      </material>
    </visual>
  </link>
  <link name="left_cover_handpinky">
    <visual>
      <geometry>
        <mesh filename="package://inmoov_description/meshes/left_cover_handpinky.stl" scale="0.001 0.001 0.001"/>
      </geometry>
      <origin rpy="0 0 3.1415" xyz="0 0 0"/>
      <material name="ccover">
        <color rgba="0.6 0.6 0.6 1"/>
      </material>
    </visual>
  </link>
  <link name="left_cover_thumb">
    <visual>
      <geometry>
        <mesh filename="package://inmoov_description/meshes/left_cover_thumb.stl" scale="0.001 0.001 0.001"/>
      </geometry>
      <origin rpy="3.1415 0 0" xyz="0 0 0"/>
      <material name="ccover">
        <color rgba="0.6 0.6 0.6 1"/>
      </material>
    </visual>
  </link>
  <link name="left_cover_index">
    <visual>
      <geometry>
        <mesh filename="package://inmoov_description/meshes/left_cover_index.stl" scale="0.001 0.001 0.001"/>
      </geometry>
      <origin rpy="0 0 3.1415" xyz="0 0 0"/>
      <material name="ccover">
        <color rgba="0.6 0.6 0.6 1"/>
      </material>
    </visual>
  </link>
  <link name="left_cover_middle">
    <visual>
      <geometry>
        <mesh filename="package://inmoov_description/meshes/left_cover_middle.stl" scale="0.001 0.001 0.001"/>
      </geometry>
      <origin rpy="0 0 3.1415" xyz="0 0 0"/>
      <material name="ccover">
        <color rgba="0.6 0.6 0.6 1"/>
      </material>
    </visual>
  </link>
  <link name="left_cover_ring">
    <visual>
      <geometry>
        <mesh filename="package://inmoov_description/meshes/left_cover_ring.stl" scale="0.001 0.001 0.001"/>
      </geometry>
      <origin rpy="0 0 3.1415" xyz="0 0 0"/>
      <material name="ccover">
        <color rgba="0.6 0.6 0.6 1"/>
      </material>
    </visual>
  </link>
  <link name="left_cover_pinky">
    <visual>
      <geometry>
        <mesh filename="package://inmoov_description/meshes/left_cover_pinky.stl" scale="0.001 0.001 0.001"/>
      </geometry>
      <origin rpy="0 0 3.1415" xyz="0 0 0"/>
      <material name="ccover">
        <color rgba="0.6 0.6 0.6 1"/>
      </material>
    </visual>
  </link>
  <joint name="left_handcover" type="fixed">
    <origin rpy="0 0 0" xyz="0.0192 0.009 -0.0977"/>
    <parent link="left_hand"/>
    <child link="left_handcover"/>
  </joint>
  <joint name="left_cover_handring" type="fixed">
    <origin rpy="0 -0.7 0" xyz="0.015 -0.009 -0.0008"/>
    <parent link="left_ring1"/>
    <child link="left_cover_handring"/>
  </joint>
  <joint name="left_cover_handpinky" type="fixed">
    <origin rpy="0 -0.7 0" xyz="0.0205 -0.01 -0.0069"/>
    <parent link="left_pinky1"/>
    <child link="left_cover_handpinky"/>
  </joint>
  <joint name="left_cover_thumb" type="fixed">
    <origin rpy="0 -3.1 0" xyz="0.02125 -0.01 -0.0047"/>
    <parent link="left_thumb1"/>
    <child link="left_cover_thumb"/>
  </joint>
  <joint name="left_cover_index" type="fixed">
    <origin rpy="-0.05 0 0" xyz="0 -0.0071 -0.012"/>
    <parent link="left_index1"/>
    <child link="left_cover_index"/>
  </joint>
  <joint name="left_cover_middle" type="fixed">
    <origin rpy="0.05 0 0" xyz="0 -0.0071 -0.012"/>
    <parent link="left_middle1"/>
    <child link="left_cover_middle"/>
  </joint>
  <joint name="left_cover_ring" type="fixed">
    <origin rpy="0.05 0.1 0" xyz="0 -0.005 -0.011"/>
    <parent link="left_ring2"/>
    <child link="left_cover_ring"/>
  </joint>
  <joint name="left_cover_pinky" type="fixed">
    <origin rpy="0.05 0.1 0" xyz="0 -0.005 -0.0105"/>
    <parent link="left_pinky2"/>
    <child link="left_cover_pinky"/>
  </joint>
  <joint name="left_hand" type="revolute">
    <axis xyz="0 0 1"/>
    <limit effort="1000.0" lower="0" upper="3.14" velocity="0.5"/>
    <origin rpy="0 0 0" xyz="0.01 -0.0144 -0.2885"/>
    <parent link="left_forearm"/>
    <child link="left_hand"/>
  </joint>
</robot>

