<?xml version="1.0" ?>
<!-- =================================================================================== -->
<!-- |    This document was autogenerated by xacro from inmoov_face.urdf.xacro         | -->
<!-- |    EDITING THIS FILE BY HAND IS NOT RECOMMENDED                                 | -->
<!-- =================================================================================== -->
<robot name="inmoov_hand" xmlns:xacro="http://ros.org/wiki/xacro">
  <link name="base_link">
    <visual>
      <geometry>
        <cylinder length="0.0001" radius="0.26"/>
      </geometry>
      <origin rpy="0 0 0" xyz="0 0 0.055"/>
      <material name="invisible">
        <color rgba="0.3 0.3 0.3 0"/>
      </material>
    </visual>
  </link>
  <link name="face">
    <visual>
      <geometry>
        <mesh filename="package://inmoov_description/meshes/face.stl" scale="0.001 0.001 0.001"/>
      </geometry>
      <origin rpy="0 0 0" xyz="0 0 0"/>
      <material name="ccover">
        <color rgba="0.6 0.6 0.6 1"/>
      </material>
    </visual>
  </link>
  <joint name="eyes_updown" type="revolute">
    <axis xyz="1 0 0"/>
    <limit effort="1000.0" lower="-1.57" upper="1.57" velocity="0.5"/>
    <origin rpy="0 0 0" xyz="0 0 0"/>
    <parent link="face"/>
    <child link="eyesupport"/>
  </joint>
  <link name="eyesupport">
    <visual>
      <geometry>
        <mesh filename="package://inmoov_description/meshes/eyesupport.stl" scale="0.001 0.001 0.001"/>
      </geometry>
      <origin rpy="0 0 0" xyz="0 0 0"/>
      <material name="cframe">
        <color rgba="0.25 0.25 0.25 1"/>
      </material>
    </visual>
  </link>
  <link name="right_eyesupport">
    <visual>
      <geometry>
        <mesh filename="package://inmoov_description/meshes/right_eyesupport.stl" scale="0.001 0.001 0.001"/>
      </geometry>
      <origin rpy="0 0 0" xyz="0 0 0"/>
      <material name="cframe">
        <color rgba="0.25 0.25 0.25 1"/>
      </material>
    </visual>
  </link>
  <link name="right_camera">
    <visual>
      <geometry>
        <mesh filename="package://inmoov_description/meshes/camera.stl" scale="0.001 0.001 0.001"/>
      </geometry>
      <origin rpy="0 0 0" xyz="0 0 0"/>
      <material name="ccamera">
        <color rgba="0.1 0.1 0.1 1"/>
      </material>
    </visual>
  </link>
  <link name="right_eye">
    <visual>
      <geometry>
        <mesh filename="package://inmoov_description/meshes/eye.stl" scale="0.001 0.001 0.001"/>
      </geometry>
      <origin rpy="0 0 0" xyz="0 0 0"/>
      <material name="ceyeball">
        <color rgba="0.7 0.7 0.7 1"/>
      </material>
    </visual>
  </link>
  <link name="right_iris">
    <visual>
      <geometry>
        <mesh filename="package://inmoov_description/meshes/iris.stl" scale="0.001 0.001 0.001"/>
      </geometry>
      <origin rpy="0 0 0" xyz="0 0 0"/>
      <material name="ciris">
        <color rgba="0.25 0.41 0.88 1"/>
      </material>
    </visual>
  </link>
  <joint name="right_camera" type="fixed">
    <origin rpy="0 0 0" xyz="0 -0.001 0"/>
    <parent link="right_eyesupport"/>
    <child link="right_camera"/>
  </joint>
  <joint name="right_eye" type="fixed">
    <origin rpy="0 0 0" xyz="0 0.003 0"/>
    <parent link="right_eyesupport"/>
    <child link="right_eye"/>
  </joint>
  <joint name="right_iris" type="fixed">
    <origin rpy="0 0 0" xyz="0 0.0061 0"/>
    <parent link="right_eyesupport"/>
    <child link="right_iris"/>
  </joint>
  <joint name="right_eye_leftright" type="revolute">
    <axis xyz="0 0 1"/>
    <limit effort="1000.0" lower="-1.57" upper="1.57" velocity="0.5"/>
    <origin rpy="0 0 0" xyz="0.033 0 -0.0036"/>
    <parent link="eyesupport"/>
    <child link="right_eyesupport"/>
  </joint>
  <link name="left_eyesupport">
    <visual>
      <geometry>
        <mesh filename="package://inmoov_description/meshes/left_eyesupport.stl" scale="0.001 0.001 0.001"/>
      </geometry>
      <origin rpy="0 0 0" xyz="0 0 0"/>
      <material name="cframe">
        <color rgba="0.25 0.25 0.25 1"/>
      </material>
    </visual>
  </link>
  <link name="left_camera">
    <visual>
      <geometry>
        <mesh filename="package://inmoov_description/meshes/camera.stl" scale="0.001 0.001 0.001"/>
      </geometry>
      <origin rpy="0 0 0" xyz="0 0 0"/>
      <material name="ccamera">
        <color rgba="0.1 0.1 0.1 1"/>
      </material>
    </visual>
  </link>
  <link name="left_eye">
    <visual>
      <geometry>
        <mesh filename="package://inmoov_description/meshes/eye.stl" scale="0.001 0.001 0.001"/>
      </geometry>
      <origin rpy="0 0 0" xyz="0 0 0"/>
      <material name="ceyeball">
        <color rgba="0.7 0.7 0.7 1"/>
      </material>
    </visual>
  </link>
  <link name="left_iris">
    <visual>
      <geometry>
        <mesh filename="package://inmoov_description/meshes/iris.stl" scale="0.001 0.001 0.001"/>
      </geometry>
      <origin rpy="0 0 0" xyz="0 0 0"/>
      <material name="ciris">
        <color rgba="0.25 0.41 0.88 1"/>
      </material>
    </visual>
  </link>
  <joint name="left_camera" type="fixed">
    <origin rpy="0 0 0" xyz="0 -0.001 0"/>
    <parent link="left_eyesupport"/>
    <child link="left_camera"/>
  </joint>
  <joint name="left_eye" type="fixed">
    <origin rpy="0 0 0" xyz="0 0.003 0"/>
    <parent link="left_eyesupport"/>
    <child link="left_eye"/>
  </joint>
  <joint name="left_iris" type="fixed">
    <origin rpy="0 0 0" xyz="0 0.0061 0"/>
    <parent link="left_eyesupport"/>
    <child link="left_iris"/>
  </joint>
  <joint name="left_eye_leftright" type="revolute">
    <axis xyz="0 0 1"/>
    <limit effort="1000.0" lower="-1.57" upper="1.57" velocity="0.5"/>
    <origin rpy="0 0 0" xyz="-0.033 0 -0.0036"/>
    <parent link="eyesupport"/>
    <child link="left_eyesupport"/>
  </joint>
  <joint name="base_to_face" type="revolute">
    <axis xyz="0 0 1"/>
    <limit effort="1000.0" lower="-3.14" upper="0" velocity="0.5"/>
    <origin rpy="0 0 0" xyz="0 0 0"/>
    <parent link="base_link"/>
    <child link="face"/>
  </joint>
</robot>

